Workbook

Sheet README
B1: CHAIN AUDIT TOOL - Pricing, Placement & Display Compliance
B2: Plan data as of Non-Alc Chain Document 9/8/2026 (+ HW Soda Hot Sheet 8/25/2025 for accounts missing from it)
B4: WHAT EACH TAB IS FOR
B5: Dashboard | C5: Team KPIs, accountability by rep, open discrepancies by type. Nothing to type.
B6: Chain Program | C6: The hot sheet. One row per brand x account: availability, merchandising callout, pricing and the expected shelf price today. Manager-owned.
B7: Promo Calendar | C7: Every promo / case-cost window with start and end dates. Status (Active / Upcoming / Expired) is automatic. Manager-owned.
B8: Visit Log | C8: Reps log each store check: observed price, tag, planogram location, in-stock, display, discrepancy type, notes and follow-up. Expected price and Price Check fill in automatically.
B9: Store History | C9: Before a visit, pick the program (and store #) to see today's plan and the last 20 visit notes for that store, newest first.
B10: Data Review | C10: Conflicts and gaps found while merging the Non-Alc Chain doc (9/8/26) with the HW Soda hot sheet (8/25/25). Work these down, then mark programs 'Current (2026)'.
B11: Lists | C11: Dropdown values: team roster, SKUs, discrepancy types, statuses.
B13: COLOR KEY
B14: Blue text | C14: Plan data the manager maintains (Chain Program, Promo Calendar, Lists).
B15: Yellow cells | C15: Cells reps fill in (Visit Log, Store History selectors).
B16: Grey cells | C16: Formulas. Do not type over them.
B17: Amber 'Confirm for 2026' | C17: Program still relies on 2025 hot-sheet data. Treat expected prices as provisional.
B19: FIELD WORKFLOW (REPS)
B20: 1. Before the visit | C20: Store History tab: pick the program and store #. Read open issues and last notes.
B21: 2. In the store | C21: Check price vs. Expected Shelf Price, shelf tag, planogram location, all authorized SKUs, and the display callout.
B22: 3. Log it | C22: Visit Log: add one row per program checked (add extra rows for SKU-specific price checks). Pick a Discrepancy Type, write notes, set Follow-up Owner, Due Date and Status.
B23: 4. Next visit | C23: Update the Status / Resolved Date of prior open rows when fixed. Do not delete history.
B25: MANAGER WORKFLOW
B26: Add a program | C26: New row at the bottom of Chain Program. Program ID must be unique (Brand | Account).
B27: Add a promo | C27: New row in Promo Calendar: pick the Program ID, SKU (or All), dates, and Unit Retail if it changes shelf price. Leave Unit Retail blank for case-cost-only windows.
B28: Weekly | C28: Dashboard: overdue follow-ups and reps with no visits in 30 days. Data Review: close questions.
B30: SHARING & PERMISSIONS (see docs/RECOMMENDATIONS.md in the repo)
B31: Plan (view-only) | C31: Store this file in SharePoint / OneDrive. Share with the team as 'Can view'. Only the manager has edit rights to Chain Program and Promo Calendar.
B32: Visit notes | C32: Excel cannot give reps 'add rows but not edit the plan' rights inside one file. Recommended: move the Visit Log to a Microsoft List (same columns) with 'create items and edit only their own' permissions. Until then, a separate shared 'Visit Log' workbook with version history works.
B34: NOTES
B35: Expected price | C35: Uses the lowest active retail promo on the visit date for that SKU (or 'All'), else Base Shelf Price. It recalculates if the plan is edited later - for a frozen audit record, move the Visit Log to Microsoft Lists.
B36: History order | C36: Store History treats lower rows as newer. Keep the Visit Log in date order (sort A-Z by Visit Date if needed).
B37: Example row | C37: Visit Log row 6 and the 'EXAMPLE - delete me' roster entry are samples. Delete both before go-live.

Sheet Dashboard
A1: CHAIN AUDIT DASHBOARD
A2: ="As of "&TEXT(TODAY(),"m/d/yyyy")&" | "&"Plan data as of Non-Alc Chain Document 9/8/2026 (+ HW Soda Hot Sheet 8/25/2025 for accounts missing from it)"
A4: KEY NUMBERS | D4: BY BRAND
A5: Programs tracked | B5: =COUNTA('Chain Program'!$A$6:$A$120) | D5: Brand | E5: Programs | F5: Active promos | G5: Open issues
A6: Programs needing 2026 confirmation | B6: =COUNTIF('Chain Program'!$U$6:$U$120,"Confirm for 2026") | D6: ZOA | E6: =COUNTIF('Chain Program'!$B$6:$B$120,D6) | F6: =COUNTIFS('Promo Calendar'!$B$6:$B$400,D6,'Promo Calendar'!$L$6:$L$400,"Active") | G6: =COUNTIFS('Visit Log'!$D$6:$D$1005,D6,'Visit Log'!$T$6:$T$1005,"Open")+COUNTIFS('Visit Log'!$D$6:$D$1005,D6,'Visit Log'!$T$6:$T$1005,"In Progress")
A7: Promo windows active today | B7: =COUNTIF('Promo Calendar'!$L$6:$L$400,"Active") | D7: Henry's | E7: =COUNTIF('Chain Program'!$B$6:$B$120,D7) | F7: =COUNTIFS('Promo Calendar'!$B$6:$B$400,D7,'Promo Calendar'!$L$6:$L$400,"Active") | G7: =COUNTIFS('Visit Log'!$D$6:$D$1005,D7,'Visit Log'!$T$6:$T$1005,"Open")+COUNTIFS('Visit Log'!$D$6:$D$1005,D7,'Visit Log'!$T$6:$T$1005,"In Progress")
A8: Promo windows starting in next 14 days | B8: =COUNTIFS('Promo Calendar'!$I$6:$I$400,">"&TODAY(),'Promo Calendar'!$I$6:$I$400,"<="&TODAY()+14) | D8: Fever-Tree | E8: =COUNTIF('Chain Program'!$B$6:$B$120,D8) | F8: =COUNTIFS('Promo Calendar'!$B$6:$B$400,D8,'Promo Calendar'!$L$6:$L$400,"Active") | G8: =COUNTIFS('Visit Log'!$D$6:$D$1005,D8,'Visit Log'!$T$6:$T$1005,"Open")+COUNTIFS('Visit Log'!$D$6:$D$1005,D8,'Visit Log'!$T$6:$T$1005,"In Progress")
A9: Visits logged, last 30 days | B9: =COUNTIFS('Visit Log'!$A$6:$A$1005,">="&TODAY()-30) | D9: Naked Life | E9: =COUNTIF('Chain Program'!$B$6:$B$120,D9) | F9: =COUNTIFS('Promo Calendar'!$B$6:$B$400,D9,'Promo Calendar'!$L$6:$L$400,"Active") | G9: =COUNTIFS('Visit Log'!$D$6:$D$1005,D9,'Visit Log'!$T$6:$T$1005,"Open")+COUNTIFS('Visit Log'!$D$6:$D$1005,D9,'Visit Log'!$T$6:$T$1005,"In Progress")
A10: Open / in-progress discrepancies | B10: =COUNTIF('Visit Log'!$T$6:$T$1005,"Open")+COUNTIF('Visit Log'!$T$6:$T$1005,"In Progress")
A11: Overdue follow-ups | B11: =COUNTIFS('Visit Log'!$T$6:$T$1005,"Open",'Visit Log'!$S$6:$S$1005,"<"&TODAY())+COUNTIFS('Visit Log'!$T$6:$T$1005,"In Progress",'Visit Log'!$S$6:$S$1005,"<"&TODAY())
A12: Shelf price match rate | B12: =IFERROR(COUNTIF('Visit Log'!$J$6:$J$1005,"Match")/(COUNTIF('Visit Log'!$J$6:$J$1005,"Match")+COUNTIF('Visit Log'!$J$6:$J$1005,"Over plan")+COUNTIF('Visit Log'!$J$6:$J$1005,"Under plan")),"No checks yet")
A15: ACCOUNTABILITY BY REP
A16: Rep | B16: Visits (30 days) | D16: Open issues owned | E16: Overdue | F16: Last visit | G16: Price checks (30 days)
A17: =IF(Lists!$A$4="","",Lists!$A$4) | B17: =IF($A17="","",COUNTIFS('Visit Log'!$B$6:$B$1005,$A17,'Visit Log'!$A$6:$A$1005,">="&TODAY()-30)) | D17: =IF($A17="","",COUNTIFS('Visit Log'!$R$6:$R$1005,$A17,'Visit Log'!$T$6:$T$1005,"Open")+COUNTIFS('Visit Log'!$R$6:$R$1005,$A17,'Visit Log'!$T$6:$T$1005,"In Progress")) | E17: =IF($A17="","",COUNTIFS('Visit Log'!$R$6:$R$1005,$A17,'Visit Log'!$T$6:$T$1005,"Open",'Visit Log'!$S$6:$S$1005,"<"&TODAY())+COUNTIFS('Visit Log'!$R$6:$R$1005,$A17,'Visit Log'!$T$6:$T$1005,"In Progress",'Visit Log'!$S$6:$S$1005,"<"&TODAY())) | F17: =IF($A17="","",IF(COUNTIFS('Visit Log'!$B$6:$B$1005,$A17)=0,"No visits",_xlfn.MAXIFS('Visit Log'!$A$6:$A$1005,'Visit Log'!$B$6:$B$1005,$A17))) | G17: =IF($A17="","",COUNTIFS('Visit Log'!$B$6:$B$1005,$A17,'Visit Log'!$A$6:$A$1005,">="&TODAY()-30,'Visit Log'!$J$6:$J$1005,"?*"))
A18: =IF(Lists!$A$5="","",Lists!$A$5) | B18: =IF($A18="","",COUNTIFS('Visit Log'!$B$6:$B$1005,$A18,'Visit Log'!$A$6:$A$1005,">="&TODAY()-30)) | D18: =IF($A18="","",COUNTIFS('Visit Log'!$R$6:$R$1005,$A18,'Visit Log'!$T$6:$T$1005,"Open")+COUNTIFS('Visit Log'!$R$6:$R$1005,$A18,'Visit Log'!$T$6:$T$1005,"In Progress")) | E18: =IF($A18="","",COUNTIFS('Visit Log'!$R$6:$R$1005,$A18,'Visit Log'!$T$6:$T$1005,"Open",'Visit Log'!$S$6:$S$1005,"<"&TODAY())+COUNTIFS('Visit Log'!$R$6:$R$1005,$A18,'Visit Log'!$T$6:$T$1005,"In Progress",'Visit Log'!$S$6:$S$1005,"<"&TODAY())) | F18: =IF($A18="","",IF(COUNTIFS('Visit Log'!$B$6:$B$1005,$A18)=0,"No visits",_xlfn.MAXIFS('Visit Log'!$A$6:$A$1005,'Visit Log'!$B$6:$B$1005,$A18))) | G18: =IF($A18="","",COUNTIFS('Visit Log'!$B$6:$B$1005,$A18,'Visit Log'!$A$6:$A$1005,">="&TODAY()-30,'Visit Log'!$J$6:$J$1005,"?*"))
A19: =IF(Lists!$A$6="","",Lists!$A$6) | B19: =IF($A19="","",COUNTIFS('Visit Log'!$B$6:$B$1005,$A19,'Visit Log'!$A$6:$A$1005,">="&TODAY()-30)) | D19: =IF($A19="","",COUNTIFS('Visit Log'!$R$6:$R$1005,$A19,'Visit Log'!$T$6:$T$1005,"Open")+COUNTIFS('Visit Log'!$R$6:$R$1005,$A19,'Visit Log'!$T$6:$T$1005,"In Progress")) | E19: =IF($A19="","",COUNTIFS('Visit Log'!$R$6:$R$1005,$A19,'Visit Log'!$T$6:$T$1005,"Open",'Visit Log'!$S$6:$S$1005,"<"&TODAY())+COUNTIFS('Visit Log'!$R$6:$R$1005,$A19,'Visit Log'!$T$6:$T$1005,"In Progress",'Visit Log'!$S$6:$S$1005,"<"&TODAY())) | F19: =IF($A19="","",IF(COUNTIFS('Visit Log'!$B$6:$B$1005,$A19)=0,"No visits",_xlfn.MAXIFS('Visit Log'!$A$6:$A$1005,'Visit Log'!$B$6:$B$1005,$A19))) | G19: =IF($A19="","",COUNTIFS('Visit Log'!$B$6:$B$1005,$A19,'Visit Log'!$A$6:$A$1005,">="&TODAY()-30,'Visit Log'!$J$6:$J$1005,"?*"))
A20: =IF(Lists!$A$7="","",Lists!$A$7) | B20: =IF($A20="","",COUNTIFS('Visit Log'!$B$6:$B$1005,$A20,'Visit Log'!$A$6:$A$1005,">="&TODAY()-30)) | D20: =IF($A20="","",COUNTIFS('Visit Log'!$R$6:$R$1005,$A20,'Visit Log'!$T$6:$T$1005,"Open")+COUNTIFS('Visit Log'!$R$6:$R$1005,$A20,'Visit Log'!$T$6:$T$1005,"In Progress")) | E20: =IF($A20="","",COUNTIFS('Visit Log'!$R$6:$R$1005,$A20,'Visit Log'!$T$6:$T$1005,"Open",'Visit Log'!$S$6:$S$1005,"<"&TODAY())+COUNTIFS('Visit Log'!$R$6:$R$1005,$A20,'Visit Log'!$T$6:$T$1005,"In Progress",'Visit Log'!$S$6:$S$1005,"<"&TODAY())) | F20: =IF($A20="","",IF(COUNTIFS('Visit Log'!$B$6:$B$1005,$A20)=0,"No visits",_xlfn.MAXIFS('Visit Log'!$A$6:$A$1005,'Visit Log'!$B$6:$B$1005,$A20))) | G20: =IF($A20="","",COUNTIFS('Visit Log'!$B$6:$B$1005,$A20,'Visit Log'!$A$6:$A$1005,">="&TODAY()-30,'Visit Log'!$J$6:$J$1005,"?*"))
A21: =IF(Lists!$A$8="","",Lists!$A$8) | B21: =IF($A21="","",COUNTIFS('Visit Log'!$B$6:$B$1005,$A21,'Visit Log'!$A$6:$A$1005,">="&TODAY()-30)) | D21: =IF($A21="","",COUNTIFS('Visit Log'!$R$6:$R$1005,$A21,'Visit Log'!$T$6:$T$1005,"Open")+COUNTIFS('Visit Log'!$R$6:$R$1005,$A21,'Visit Log'!$T$6:$T$1005,"In Progress")) | E21: =IF($A21="","",COUNTIFS('Visit Log'!$R$6:$R$1005,$A21,'Visit Log'!$T$6:$T$1005,"Open",'Visit Log'!$S$6:$S$1005,"<"&TODAY())+COUNTIFS('Visit Log'!$R$6:$R$1005,$A21,'Visit Log'!$T$6:$T$1005,"In Progress",'Visit Log'!$S$6:$S$1005,"<"&TODAY())) | F21: =IF($A21="","",IF(COUNTIFS('Visit Log'!$B$6:$B$1005,$A21)=0,"No visits",_xlfn.MAXIFS('Visit Log'!$A$6:$A$1005,'Visit Log'!$B$6:$B$1005,$A21))) | G21: =IF($A21="","",COUNTIFS('Visit Log'!$B$6:$B$1005,$A21,'Visit Log'!$A$6:$A$1005,">="&TODAY()-30,'Visit Log'!$J$6:$J$1005,"?*"))
A22: =IF(Lists!$A$9="","",Lists!$A$9) | B22: =IF($A22="","",COUNTIFS('Visit Log'!$B$6:$B$1005,$A22,'Visit Log'!$A$6:$A$1005,">="&TODAY()-30)) | D22: =IF($A22="","",COUNTIFS('Visit Log'!$R$6:$R$1005,$A22,'Visit Log'!$T$6:$T$1005,"Open")+COUNTIFS('Visit Log'!$R$6:$R$1005,$A22,'Visit Log'!$T$6:$T$1005,"In Progress")) | E22: =IF($A22="","",COUNTIFS('Visit Log'!$R$6:$R$1005,$A22,'Visit Log'!$T$6:$T$1005,"Open",'Visit Log'!$S$6:$S$1005,"<"&TODAY())+COUNTIFS('Visit Log'!$R$6:$R$1005,$A22,'Visit Log'!$T$6:$T$1005,"In Progress",'Visit Log'!$S$6:$S$1005,"<"&TODAY())) | F22: =IF($A22="","",IF(COUNTIFS('Visit Log'!$B$6:$B$1005,$A22)=0,"No visits",_xlfn.MAXIFS('Visit Log'!$A$6:$A$1005,'Visit Log'!$B$6:$B$1005,$A22))) | G22: =IF($A22="","",COUNTIFS('Visit Log'!$B$6:$B$1005,$A22,'Visit Log'!$A$6:$A$1005,">="&TODAY()-30,'Visit Log'!$J$6:$J$1005,"?*"))
A23: =IF(Lists!$A$10="","",Lists!$A$10) | B23: =IF($A23="","",COUNTIFS('Visit Log'!$B$6:$B$1005,$A23,'Visit Log'!$A$6:$A$1005,">="&TODAY()-30)) | D23: =IF($A23="","",COUNTIFS('Visit Log'!$R$6:$R$1005,$A23,'Visit Log'!$T$6:$T$1005,"Open")+COUNTIFS('Visit Log'!$R$6:$R$1005,$A23,'Visit Log'!$T$6:$T$1005,"In Progress")) | E23: =IF($A23="","",COUNTIFS('Visit Log'!$R$6:$R$1005,$A23,'Visit Log'!$T$6:$T$1005,"Open",'Visit Log'!$S$6:$S$1005,"<"&TODAY())+COUNTIFS('Visit Log'!$R$6:$R$1005,$A23,'Visit Log'!$T$6:$T$1005,"In Progress",'Visit Log'!$S$6:$S$1005,"<"&TODAY())) | F23: =IF($A23="","",IF(COUNTIFS('Visit Log'!$B$6:$B$1005,$A23)=0,"No visits",_xlfn.MAXIFS('Visit Log'!$A$6:$A$1005,'Visit Log'!$B$6:$B$1005,$A23))) | G23: =IF($A23="","",COUNTIFS('Visit Log'!$B$6:$B$1005,$A23,'Visit Log'!$A$6:$A$1005,">="&TODAY()-30,'Visit Log'!$J$6:$J$1005,"?*"))
A24: =IF(Lists!$A$11="","",Lists!$A$11) | B24: =IF($A24="","",COUNTIFS('Visit Log'!$B$6:$B$1005,$A24,'Visit Log'!$A$6:$A$1005,">="&TODAY()-30)) | D24: =IF($A24="","",COUNTIFS('Visit Log'!$R$6:$R$1005,$A24,'Visit Log'!$T$6:$T$1005,"Open")+COUNTIFS('Visit Log'!$R$6:$R$1005,$A24,'Visit Log'!$T$6:$T$1005,"In Progress")) | E24: =IF($A24="","",COUNTIFS('Visit Log'!$R$6:$R$1005,$A24,'Visit Log'!$T$6:$T$1005,"Open",'Visit Log'!$S$6:$S$1005,"<"&TODAY())+COUNTIFS('Visit Log'!$R$6:$R$1005,$A24,'Visit Log'!$T$6:$T$1005,"In Progress",'Visit Log'!$S$6:$S$1005,"<"&TODAY())) | F24: =IF($A24="","",IF(COUNTIFS('Visit Log'!$B$6:$B$1005,$A24)=0,"No visits",_xlfn.MAXIFS('Visit Log'!$A$6:$A$1005,'Visit Log'!$B$6:$B$1005,$A24))) | G24: =IF($A24="","",COUNTIFS('Visit Log'!$B$6:$B$1005,$A24,'Visit Log'!$A$6:$A$1005,">="&TODAY()-30,'Visit Log'!$J$6:$J$1005,"?*"))
A25: =IF(Lists!$A$12="","",Lists!$A$12) | B25: =IF($A25="","",COUNTIFS('Visit Log'!$B$6:$B$1005,$A25,'Visit Log'!$A$6:$A$1005,">="&TODAY()-30)) | D25: =IF($A25="","",COUNTIFS('Visit Log'!$R$6:$R$1005,$A25,'Visit Log'!$T$6:$T$1005,"Open")+COUNTIFS('Visit Log'!$R$6:$R$1005,$A25,'Visit Log'!$T$6:$T$1005,"In Progress")) | E25: =IF($A25="","",COUNTIFS('Visit Log'!$R$6:$R$1005,$A25,'Visit Log'!$T$6:$T$1005,"Open",'Visit Log'!$S$6:$S$1005,"<"&TODAY())+COUNTIFS('Visit Log'!$R$6:$R$1005,$A25,'Visit Log'!$T$6:$T$1005,"In Progress",'Visit Log'!$S$6:$S$1005,"<"&TODAY())) | F25: =IF($A25="","",IF(COUNTIFS('Visit Log'!$B$6:$B$1005,$A25)=0,"No visits",_xlfn.MAXIFS('Visit Log'!$A$6:$A$1005,'Visit Log'!$B$6:$B$1005,$A25))) | G25: =IF($A25="","",COUNTIFS('Visit Log'!$B$6:$B$1005,$A25,'Visit Log'!$A$6:$A$1005,">="&TODAY()-30,'Visit Log'!$J$6:$J$1005,"?*"))
A26: =IF(Lists!$A$13="","",Lists!$A$13) | B26: =IF($A26="","",COUNTIFS('Visit Log'!$B$6:$B$1005,$A26,'Visit Log'!$A$6:$A$1005,">="&TODAY()-30)) | D26: =IF($A26="","",COUNTIFS('Visit Log'!$R$6:$R$1005,$A26,'Visit Log'!$T$6:$T$1005,"Open")+COUNTIFS('Visit Log'!$R$6:$R$1005,$A26,'Visit Log'!$T$6:$T$1005,"In Progress")) | E26: =IF($A26="","",COUNTIFS('Visit Log'!$R$6:$R$1005,$A26,'Visit Log'!$T$6:$T$1005,"Open",'Visit Log'!$S$6:$S$1005,"<"&TODAY())+COUNTIFS('Visit Log'!$R$6:$R$1005,$A26,'Visit Log'!$T$6:$T$1005,"In Progress",'Visit Log'!$S$6:$S$1005,"<"&TODAY())) | F26: =IF($A26="","",IF(COUNTIFS('Visit Log'!$B$6:$B$1005,$A26)=0,"No visits",_xlfn.MAXIFS('Visit Log'!$A$6:$A$1005,'Visit Log'!$B$6:$B$1005,$A26))) | G26: =IF($A26="","",COUNTIFS('Visit Log'!$B$6:$B$1005,$A26,'Visit Log'!$A$6:$A$1005,">="&TODAY()-30,'Visit Log'!$J$6:$J$1005,"?*"))
A27: =IF(Lists!$A$14="","",Lists!$A$14) | B27: =IF($A27="","",COUNTIFS('Visit Log'!$B$6:$B$1005,$A27,'Visit Log'!$A$6:$A$1005,">="&TODAY()-30)) | D27: =IF($A27="","",COUNTIFS('Visit Log'!$R$6:$R$1005,$A27,'Visit Log'!$T$6:$T$1005,"Open")+COUNTIFS('Visit Log'!$R$6:$R$1005,$A27,'Visit Log'!$T$6:$T$1005,"In Progress")) | E27: =IF($A27="","",COUNTIFS('Visit Log'!$R$6:$R$1005,$A27,'Visit Log'!$T$6:$T$1005,"Open",'Visit Log'!$S$6:$S$1005,"<"&TODAY())+COUNTIFS('Visit Log'!$R$6:$R$1005,$A27,'Visit Log'!$T$6:$T$1005,"In Progress",'Visit Log'!$S$6:$S$1005,"<"&TODAY())) | F27: =IF($A27="","",IF(COUNTIFS('Visit Log'!$B$6:$B$1005,$A27)=0,"No visits",_xlfn.MAXIFS('Visit Log'!$A$6:$A$1005,'Visit Log'!$B$6:$B$1005,$A27))) | G27: =IF($A27="","",COUNTIFS('Visit Log'!$B$6:$B$1005,$A27,'Visit Log'!$A$6:$A$1005,">="&TODAY()-30,'Visit Log'!$J$6:$J$1005,"?*"))
A28: =IF(Lists!$A$15="","",Lists!$A$15) | B28: =IF($A28="","",COUNTIFS('Visit Log'!$B$6:$B$1005,$A28,'Visit Log'!$A$6:$A$1005,">="&TODAY()-30)) | D28: =IF($A28="","",COUNTIFS('Visit Log'!$R$6:$R$1005,$A28,'Visit Log'!$T$6:$T$1005,"Open")+COUNTIFS('Visit Log'!$R$6:$R$1005,$A28,'Visit Log'!$T$6:$T$1005,"In Progress")) | E28: =IF($A28="","",COUNTIFS('Visit Log'!$R$6:$R$1005,$A28,'Visit Log'!$T$6:$T$1005,"Open",'Visit Log'!$S$6:$S$1005,"<"&TODAY())+COUNTIFS('Visit Log'!$R$6:$R$1005,$A28,'Visit Log'!$T$6:$T$1005,"In Progress",'Visit Log'!$S$6:$S$1005,"<"&TODAY())) | F28: =IF($A28="","",IF(COUNTIFS('Visit Log'!$B$6:$B$1005,$A28)=0,"No visits",_xlfn.MAXIFS('Visit Log'!$A$6:$A$1005,'Visit Log'!$B$6:$B$1005,$A28))) | G28: =IF($A28="","",COUNTIFS('Visit Log'!$B$6:$B$1005,$A28,'Visit Log'!$A$6:$A$1005,">="&TODAY()-30,'Visit Log'!$J$6:$J$1005,"?*"))
A29: =IF(Lists!$A$16="","",Lists!$A$16) | B29: =IF($A29="","",COUNTIFS('Visit Log'!$B$6:$B$1005,$A29,'Visit Log'!$A$6:$A$1005,">="&TODAY()-30)) | D29: =IF($A29="","",COUNTIFS('Visit Log'!$R$6:$R$1005,$A29,'Visit Log'!$T$6:$T$1005,"Open")+COUNTIFS('Visit Log'!$R$6:$R$1005,$A29,'Visit Log'!$T$6:$T$1005,"In Progress")) | E29: =IF($A29="","",COUNTIFS('Visit Log'!$R$6:$R$1005,$A29,'Visit Log'!$T$6:$T$1005,"Open",'Visit Log'!$S$6:$S$1005,"<"&TODAY())+COUNTIFS('Visit Log'!$R$6:$R$1005,$A29,'Visit Log'!$T$6:$T$1005,"In Progress",'Visit Log'!$S$6:$S$1005,"<"&TODAY())) | F29: =IF($A29="","",IF(COUNTIFS('Visit Log'!$B$6:$B$1005,$A29)=0,"No visits",_xlfn.MAXIFS('Visit Log'!$A$6:$A$1005,'Visit Log'!$B$6:$B$1005,$A29))) | G29: =IF($A29="","",COUNTIFS('Visit Log'!$B$6:$B$1005,$A29,'Visit Log'!$A$6:$A$1005,">="&TODAY()-30,'Visit Log'!$J$6:$J$1005,"?*"))
A30: =IF(Lists!$A$17="","",Lists!$A$17) | B30: =IF($A30="","",COUNTIFS('Visit Log'!$B$6:$B$1005,$A30,'Visit Log'!$A$6:$A$1005,">="&TODAY()-30)) | D30: =IF($A30="","",COUNTIFS('Visit Log'!$R$6:$R$1005,$A30,'Visit Log'!$T$6:$T$1005,"Open")+COUNTIFS('Visit Log'!$R$6:$R$1005,$A30,'Visit Log'!$T$6:$T$1005,"In Progress")) | E30: =IF($A30="","",COUNTIFS('Visit Log'!$R$6:$R$1005,$A30,'Visit Log'!$T$6:$T$1005,"Open",'Visit Log'!$S$6:$S$1005,"<"&TODAY())+COUNTIFS('Visit Log'!$R$6:$R$1005,$A30,'Visit Log'!$T$6:$T$1005,"In Progress",'Visit Log'!$S$6:$S$1005,"<"&TODAY())) | F30: =IF($A30="","",IF(COUNTIFS('Visit Log'!$B$6:$B$1005,$A30)=0,"No visits",_xlfn.MAXIFS('Visit Log'!$A$6:$A$1005,'Visit Log'!$B$6:$B$1005,$A30))) | G30: =IF($A30="","",COUNTIFS('Visit Log'!$B$6:$B$1005,$A30,'Visit Log'!$A$6:$A$1005,">="&TODAY()-30,'Visit Log'!$J$6:$J$1005,"?*"))
A31: =IF(Lists!$A$18="","",Lists!$A$18) | B31: =IF($A31="","",COUNTIFS('Visit Log'!$B$6:$B$1005,$A31,'Visit Log'!$A$6:$A$1005,">="&TODAY()-30)) | D31: =IF($A31="","",COUNTIFS('Visit Log'!$R$6:$R$1005,$A31,'Visit Log'!$T$6:$T$1005,"Open")+COUNTIFS('Visit Log'!$R$6:$R$1005,$A31,'Visit Log'!$T$6:$T$1005,"In Progress")) | E31: =IF($A31="","",COUNTIFS('Visit Log'!$R$6:$R$1005,$A31,'Visit Log'!$T$6:$T$1005,"Open",'Visit Log'!$S$6:$S$1005,"<"&TODAY())+COUNTIFS('Visit Log'!$R$6:$R$1005,$A31,'Visit Log'!$T$6:$T$1005,"In Progress",'Visit Log'!$S$6:$S$1005,"<"&TODAY())) | F31: =IF($A31="","",IF(COUNTIFS('Visit Log'!$B$6:$B$1005,$A31)=0,"No visits",_xlfn.MAXIFS('Visit Log'!$A$6:$A$1005,'Visit Log'!$B$6:$B$1005,$A31))) | G31: =IF($A31="","",COUNTIFS('Visit Log'!$B$6:$B$1005,$A31,'Visit Log'!$A$6:$A$1005,">="&TODAY()-30,'Visit Log'!$J$6:$J$1005,"?*"))
A32: =IF(Lists!$A$19="","",Lists!$A$19) | B32: =IF($A32="","",COUNTIFS('Visit Log'!$B$6:$B$1005,$A32,'Visit Log'!$A$6:$A$1005,">="&TODAY()-30)) | D32: =IF($A32="","",COUNTIFS('Visit Log'!$R$6:$R$1005,$A32,'Visit Log'!$T$6:$T$1005,"Open")+COUNTIFS('Visit Log'!$R$6:$R$1005,$A32,'Visit Log'!$T$6:$T$1005,"In Progress")) | E32: =IF($A32="","",COUNTIFS('Visit Log'!$R$6:$R$1005,$A32,'Visit Log'!$T$6:$T$1005,"Open",'Visit Log'!$S$6:$S$1005,"<"&TODAY())+COUNTIFS('Visit Log'!$R$6:$R$1005,$A32,'Visit Log'!$T$6:$T$1005,"In Progress",'Visit Log'!$S$6:$S$1005,"<"&TODAY())) | F32: =IF($A32="","",IF(COUNTIFS('Visit Log'!$B$6:$B$1005,$A32)=0,"No visits",_xlfn.MAXIFS('Visit Log'!$A$6:$A$1005,'Visit Log'!$B$6:$B$1005,$A32))) | G32: =IF($A32="","",COUNTIFS('Visit Log'!$B$6:$B$1005,$A32,'Visit Log'!$A$6:$A$1005,">="&TODAY()-30,'Visit Log'!$J$6:$J$1005,"?*"))
A33: =IF(Lists!$A$20="","",Lists!$A$20) | B33: =IF($A33="","",COUNTIFS('Visit Log'!$B$6:$B$1005,$A33,'Visit Log'!$A$6:$A$1005,">="&TODAY()-30)) | D33: =IF($A33="","",COUNTIFS('Visit Log'!$R$6:$R$1005,$A33,'Visit Log'!$T$6:$T$1005,"Open")+COUNTIFS('Visit Log'!$R$6:$R$1005,$A33,'Visit Log'!$T$6:$T$1005,"In Progress")) | E33: =IF($A33="","",COUNTIFS('Visit Log'!$R$6:$R$1005,$A33,'Visit Log'!$T$6:$T$1005,"Open",'Visit Log'!$S$6:$S$1005,"<"&TODAY())+COUNTIFS('Visit Log'!$R$6:$R$1005,$A33,'Visit Log'!$T$6:$T$1005,"In Progress",'Visit Log'!$S$6:$S$1005,"<"&TODAY())) | F33: =IF($A33="","",IF(COUNTIFS('Visit Log'!$B$6:$B$1005,$A33)=0,"No visits",_xlfn.MAXIFS('Visit Log'!$A$6:$A$1005,'Visit Log'!$B$6:$B$1005,$A33))) | G33: =IF($A33="","",COUNTIFS('Visit Log'!$B$6:$B$1005,$A33,'Visit Log'!$A$6:$A$1005,">="&TODAY()-30,'Visit Log'!$J$6:$J$1005,"?*"))
A34: =IF(Lists!$A$21="","",Lists!$A$21) | B34: =IF($A34="","",COUNTIFS('Visit Log'!$B$6:$B$1005,$A34,'Visit Log'!$A$6:$A$1005,">="&TODAY()-30)) | D34: =IF($A34="","",COUNTIFS('Visit Log'!$R$6:$R$1005,$A34,'Visit Log'!$T$6:$T$1005,"Open")+COUNTIFS('Visit Log'!$R$6:$R$1005,$A34,'Visit Log'!$T$6:$T$1005,"In Progress")) | E34: =IF($A34="","",COUNTIFS('Visit Log'!$R$6:$R$1005,$A34,'Visit Log'!$T$6:$T$1005,"Open",'Visit Log'!$S$6:$S$1005,"<"&TODAY())+COUNTIFS('Visit Log'!$R$6:$R$1005,$A34,'Visit Log'!$T$6:$T$1005,"In Progress",'Visit Log'!$S$6:$S$1005,"<"&TODAY())) | F34: =IF($A34="","",IF(COUNTIFS('Visit Log'!$B$6:$B$1005,$A34)=0,"No visits",_xlfn.MAXIFS('Visit Log'!$A$6:$A$1005,'Visit Log'!$B$6:$B$1005,$A34))) | G34: =IF($A34="","",COUNTIFS('Visit Log'!$B$6:$B$1005,$A34,'Visit Log'!$A$6:$A$1005,">="&TODAY()-30,'Visit Log'!$J$6:$J$1005,"?*"))
A35: =IF(Lists!$A$22="","",Lists!$A$22) | B35: =IF($A35="","",COUNTIFS('Visit Log'!$B$6:$B$1005,$A35,'Visit Log'!$A$6:$A$1005,">="&TODAY()-30)) | D35: =IF($A35="","",COUNTIFS('Visit Log'!$R$6:$R$1005,$A35,'Visit Log'!$T$6:$T$1005,"Open")+COUNTIFS('Visit Log'!$R$6:$R$1005,$A35,'Visit Log'!$T$6:$T$1005,"In Progress")) | E35: =IF($A35="","",COUNTIFS('Visit Log'!$R$6:$R$1005,$A35,'Visit Log'!$T$6:$T$1005,"Open",'Visit Log'!$S$6:$S$1005,"<"&TODAY())+COUNTIFS('Visit Log'!$R$6:$R$1005,$A35,'Visit Log'!$T$6:$T$1005,"In Progress",'Visit Log'!$S$6:$S$1005,"<"&TODAY())) | F35: =IF($A35="","",IF(COUNTIFS('Visit Log'!$B$6:$B$1005,$A35)=0,"No visits",_xlfn.MAXIFS('Visit Log'!$A$6:$A$1005,'Visit Log'!$B$6:$B$1005,$A35))) | G35: =IF($A35="","",COUNTIFS('Visit Log'!$B$6:$B$1005,$A35,'Visit Log'!$A$6:$A$1005,">="&TODAY()-30,'Visit Log'!$J$6:$J$1005,"?*"))
A36: =IF(Lists!$A$23="","",Lists!$A$23) | B36: =IF($A36="","",COUNTIFS('Visit Log'!$B$6:$B$1005,$A36,'Visit Log'!$A$6:$A$1005,">="&TODAY()-30)) | D36: =IF($A36="","",COUNTIFS('Visit Log'!$R$6:$R$1005,$A36,'Visit Log'!$T$6:$T$1005,"Open")+COUNTIFS('Visit Log'!$R$6:$R$1005,$A36,'Visit Log'!$T$6:$T$1005,"In Progress")) | E36: =IF($A36="","",COUNTIFS('Visit Log'!$R$6:$R$1005,$A36,'Visit Log'!$T$6:$T$1005,"Open",'Visit Log'!$S$6:$S$1005,"<"&TODAY())+COUNTIFS('Visit Log'!$R$6:$R$1005,$A36,'Visit Log'!$T$6:$T$1005,"In Progress",'Visit Log'!$S$6:$S$1005,"<"&TODAY())) | F36: =IF($A36="","",IF(COUNTIFS('Visit Log'!$B$6:$B$1005,$A36)=0,"No visits",_xlfn.MAXIFS('Visit Log'!$A$6:$A$1005,'Visit Log'!$B$6:$B$1005,$A36))) | G36: =IF($A36="","",COUNTIFS('Visit Log'!$B$6:$B$1005,$A36,'Visit Log'!$A$6:$A$1005,">="&TODAY()-30,'Visit Log'!$J$6:$J$1005,"?*"))
A37: =IF(Lists!$A$24="","",Lists!$A$24) | B37: =IF($A37="","",COUNTIFS('Visit Log'!$B$6:$B$1005,$A37,'Visit Log'!$A$6:$A$1005,">="&TODAY()-30)) | D37: =IF($A37="","",COUNTIFS('Visit Log'!$R$6:$R$1005,$A37,'Visit Log'!$T$6:$T$1005,"Open")+COUNTIFS('Visit Log'!$R$6:$R$1005,$A37,'Visit Log'!$T$6:$T$1005,"In Progress")) | E37: =IF($A37="","",COUNTIFS('Visit Log'!$R$6:$R$1005,$A37,'Visit Log'!$T$6:$T$1005,"Open",'Visit Log'!$S$6:$S$1005,"<"&TODAY())+COUNTIFS('Visit Log'!$R$6:$R$1005,$A37,'Visit Log'!$T$6:$T$1005,"In Progress",'Visit Log'!$S$6:$S$1005,"<"&TODAY())) | F37: =IF($A37="","",IF(COUNTIFS('Visit Log'!$B$6:$B$1005,$A37)=0,"No visits",_xlfn.MAXIFS('Visit Log'!$A$6:$A$1005,'Visit Log'!$B$6:$B$1005,$A37))) | G37: =IF($A37="","",COUNTIFS('Visit Log'!$B$6:$B$1005,$A37,'Visit Log'!$A$6:$A$1005,">="&TODAY()-30,'Visit Log'!$J$6:$J$1005,"?*"))
A38: =IF(Lists!$A$25="","",Lists!$A$25) | B38: =IF($A38="","",COUNTIFS('Visit Log'!$B$6:$B$1005,$A38,'Visit Log'!$A$6:$A$1005,">="&TODAY()-30)) | D38: =IF($A38="","",COUNTIFS('Visit Log'!$R$6:$R$1005,$A38,'Visit Log'!$T$6:$T$1005,"Open")+COUNTIFS('Visit Log'!$R$6:$R$1005,$A38,'Visit Log'!$T$6:$T$1005,"In Progress")) | E38: =IF($A38="","",COUNTIFS('Visit Log'!$R$6:$R$1005,$A38,'Visit Log'!$T$6:$T$1005,"Open",'Visit Log'!$S$6:$S$1005,"<"&TODAY())+COUNTIFS('Visit Log'!$R$6:$R$1005,$A38,'Visit Log'!$T$6:$T$1005,"In Progress",'Visit Log'!$S$6:$S$1005,"<"&TODAY())) | F38: =IF($A38="","",IF(COUNTIFS('Visit Log'!$B$6:$B$1005,$A38)=0,"No visits",_xlfn.MAXIFS('Visit Log'!$A$6:$A$1005,'Visit Log'!$B$6:$B$1005,$A38))) | G38: =IF($A38="","",COUNTIFS('Visit Log'!$B$6:$B$1005,$A38,'Visit Log'!$A$6:$A$1005,">="&TODAY()-30,'Visit Log'!$J$6:$J$1005,"?*"))
A39: =IF(Lists!$A$26="","",Lists!$A$26) | B39: =IF($A39="","",COUNTIFS('Visit Log'!$B$6:$B$1005,$A39,'Visit Log'!$A$6:$A$1005,">="&TODAY()-30)) | D39: =IF($A39="","",COUNTIFS('Visit Log'!$R$6:$R$1005,$A39,'Visit Log'!$T$6:$T$1005,"Open")+COUNTIFS('Visit Log'!$R$6:$R$1005,$A39,'Visit Log'!$T$6:$T$1005,"In Progress")) | E39: =IF($A39="","",COUNTIFS('Visit Log'!$R$6:$R$1005,$A39,'Visit Log'!$T$6:$T$1005,"Open",'Visit Log'!$S$6:$S$1005,"<"&TODAY())+COUNTIFS('Visit Log'!$R$6:$R$1005,$A39,'Visit Log'!$T$6:$T$1005,"In Progress",'Visit Log'!$S$6:$S$1005,"<"&TODAY())) | F39: =IF($A39="","",IF(COUNTIFS('Visit Log'!$B$6:$B$1005,$A39)=0,"No visits",_xlfn.MAXIFS('Visit Log'!$A$6:$A$1005,'Visit Log'!$B$6:$B$1005,$A39))) | G39: =IF($A39="","",COUNTIFS('Visit Log'!$B$6:$B$1005,$A39,'Visit Log'!$A$6:$A$1005,">="&TODAY()-30,'Visit Log'!$J$6:$J$1005,"?*"))
A40: =IF(Lists!$A$27="","",Lists!$A$27) | B40: =IF($A40="","",COUNTIFS('Visit Log'!$B$6:$B$1005,$A40,'Visit Log'!$A$6:$A$1005,">="&TODAY()-30)) | D40: =IF($A40="","",COUNTIFS('Visit Log'!$R$6:$R$1005,$A40,'Visit Log'!$T$6:$T$1005,"Open")+COUNTIFS('Visit Log'!$R$6:$R$1005,$A40,'Visit Log'!$T$6:$T$1005,"In Progress")) | E40: =IF($A40="","",COUNTIFS('Visit Log'!$R$6:$R$1005,$A40,'Visit Log'!$T$6:$T$1005,"Open",'Visit Log'!$S$6:$S$1005,"<"&TODAY())+COUNTIFS('Visit Log'!$R$6:$R$1005,$A40,'Visit Log'!$T$6:$T$1005,"In Progress",'Visit Log'!$S$6:$S$1005,"<"&TODAY())) | F40: =IF($A40="","",IF(COUNTIFS('Visit Log'!$B$6:$B$1005,$A40)=0,"No visits",_xlfn.MAXIFS('Visit Log'!$A$6:$A$1005,'Visit Log'!$B$6:$B$1005,$A40))) | G40: =IF($A40="","",COUNTIFS('Visit Log'!$B$6:$B$1005,$A40,'Visit Log'!$A$6:$A$1005,">="&TODAY()-30,'Visit Log'!$J$6:$J$1005,"?*"))
A41: =IF(Lists!$A$28="","",Lists!$A$28) | B41: =IF($A41="","",COUNTIFS('Visit Log'!$B$6:$B$1005,$A41,'Visit Log'!$A$6:$A$1005,">="&TODAY()-30)) | D41: =IF($A41="","",COUNTIFS('Visit Log'!$R$6:$R$1005,$A41,'Visit Log'!$T$6:$T$1005,"Open")+COUNTIFS('Visit Log'!$R$6:$R$1005,$A41,'Visit Log'!$T$6:$T$1005,"In Progress")) | E41: =IF($A41="","",COUNTIFS('Visit Log'!$R$6:$R$1005,$A41,'Visit Log'!$T$6:$T$1005,"Open",'Visit Log'!$S$6:$S$1005,"<"&TODAY())+COUNTIFS('Visit Log'!$R$6:$R$1005,$A41,'Visit Log'!$T$6:$T$1005,"In Progress",'Visit Log'!$S$6:$S$1005,"<"&TODAY())) | F41: =IF($A41="","",IF(COUNTIFS('Visit Log'!$B$6:$B$1005,$A41)=0,"No visits",_xlfn.MAXIFS('Visit Log'!$A$6:$A$1005,'Visit Log'!$B$6:$B$1005,$A41))) | G41: =IF($A41="","",COUNTIFS('Visit Log'!$B$6:$B$1005,$A41,'Visit Log'!$A$6:$A$1005,">="&TODAY()-30,'Visit Log'!$J$6:$J$1005,"?*"))
A42: =IF(Lists!$A$29="","",Lists!$A$29) | B42: =IF($A42="","",COUNTIFS('Visit Log'!$B$6:$B$1005,$A42,'Visit Log'!$A$6:$A$1005,">="&TODAY()-30)) | D42: =IF($A42="","",COUNTIFS('Visit Log'!$R$6:$R$1005,$A42,'Visit Log'!$T$6:$T$1005,"Open")+COUNTIFS('Visit Log'!$R$6:$R$1005,$A42,'Visit Log'!$T$6:$T$1005,"In Progress")) | E42: =IF($A42="","",COUNTIFS('Visit Log'!$R$6:$R$1005,$A42,'Visit Log'!$T$6:$T$1005,"Open",'Visit Log'!$S$6:$S$1005,"<"&TODAY())+COUNTIFS('Visit Log'!$R$6:$R$1005,$A42,'Visit Log'!$T$6:$T$1005,"In Progress",'Visit Log'!$S$6:$S$1005,"<"&TODAY())) | F42: =IF($A42="","",IF(COUNTIFS('Visit Log'!$B$6:$B$1005,$A42)=0,"No visits",_xlfn.MAXIFS('Visit Log'!$A$6:$A$1005,'Visit Log'!$B$6:$B$1005,$A42))) | G42: =IF($A42="","",COUNTIFS('Visit Log'!$B$6:$B$1005,$A42,'Visit Log'!$A$6:$A$1005,">="&TODAY()-30,'Visit Log'!$J$6:$J$1005,"?*"))
A44: OPEN DISCREPANCIES BY TYPE
...

Sheet Chain Program
A1: CHAIN PROGRAM - HOT SHEET
A2: Plan data as of Non-Alc Chain Document 9/8/2026 (+ HW Soda Hot Sheet 8/25/2025 for accounts missing from it). Blue text = manager inputs. Grey columns = formulas (do not type).
A3: Today: | B3: =TODAY()
A4: CHANNEL | H4: AVAILABILITY | J4: MERCHANDISING | K4: PRICING / PROMOTION | R4: EXECUTION & ACCOUNTABILITY
A5: Program ID | B5: Brand | C5: Chain / Banner | D5: Account / Division | E5: Market | F5: Outlets by Market Unit | G5: Total Outlets | H5: Authorized SKUs / Flavors | I5: Case Recommendation | J5: Shelf Location / Display Callout | K5: Case Cost / Frontline | L5: EDV / SRP | M5: Base Shelf Price ($) | N5: Promo Timing | O5: Current Promo (today) | P5: Expected Shelf Price Today ($) | Q5: Next Promo Start | R5: Execution Priority / Callouts | S5: Owner | T5: Source | U5: Data Status | V5: Last Verified | W5: Visits (30 days) | X5: Open Issues | Y5: Last Visit
A6: ZOA | Mountain West North | B6: ZOA | C6: Albertsons/Safeway | D6: Mountain West North | E6: ID / MT / WY | H6: ZOA core SKUs | J6: Promo display where authorized | L6: Promo 2 for $4 | N6: Aug-Dec 2026 | O6: =IF($A6="","",IF(COUNTIFS('Promo Calendar'!$A$6:$A$400,$A6,'Promo Calendar'!$L$6:$L$400,"Active")=0,"None active",INDEX('Promo Calendar'!$F$6:$F$400,MATCH($A6,'Promo Calendar'!$O$6:$O$400,0))&IF(COUNTIFS('Promo Calendar'!$A$6:$A$400,$A6,'Promo Calendar'!$L$6:$L$400,"Active")>1," (+"&(COUNTIFS('Promo Calendar'!$A$6:$A$400,$A6,'Promo Calendar'!$L$6:$L$400,"Active")-1)&" more)",""))) | P6: =IF($A6="","",IF(COUNTIFS('Promo Calendar'!$A$6:$A$400,$A6,'Promo Calendar'!$L$6:$L$400,"Active",'Promo Calendar'!$G$6:$G$400,">0")>0,_xlfn.MINIFS('Promo Calendar'!$G$6:$G$400,'Promo Calendar'!$A$6:$A$400,$A6,'Promo Calendar'!$L$6:$L$400,"Active",'Promo Calendar'!$G$6:$G$400,">0"),IF(M6="","Not set",M6))) | Q6: =IF($A6="","",IF(COUNTIFS('Promo Calendar'!$A$6:$A$400,$A6,'Promo Calendar'!$I$6:$I$400,">"&TODAY())=0,"None scheduled",_xlfn.MINIFS('Promo Calendar'!$I$6:$I$400,'Promo Calendar'!$A$6:$A$400,$A6,'Promo Calendar'!$I$6:$I$400,">"&TODAY()))) | R6: Promote ZOA at 2 for $4. | T6: Non-Alc Chain 9/8/26 | U6: Current (2026) | W6: =IF($A6="","",COUNTIFS('Visit Log'!$C$6:$C$1005,$A6,'Visit Log'!$A$6:$A$1005,">="&TODAY()-30)) | X6: =IF($A6="","",COUNTIFS('Visit Log'!$C$6:$C$1005,$A6,'Visit Log'!$T$6:$T$1005,"Open")+COUNTIFS('Visit Log'!$C$6:$C$1005,$A6,'Visit Log'!$T$6:$T$1005,"In Progress")) | Y6: =IF($A6="","",IF(COUNTIFS('Visit Log'!$C$6:$C$1005,$A6)=0,"No visits",_xlfn.MAXIFS('Visit Log'!$A$6:$A$1005,'Visit Log'!$C$6:$C$1005,$A6)))
A7: ZOA | Mountain West South | B7: ZOA | C7: Albertsons/Safeway | D7: Mountain West South | E7: CO / WY | H7: ZOA core SKUs | J7: Promo display where authorized | L7: Promo 2 for $4 | N7: Aug-Dec 2026 | O7: =IF($A7="","",IF(COUNTIFS('Promo Calendar'!$A$6:$A$400,$A7,'Promo Calendar'!$L$6:$L$400,"Active")=0,"None active",INDEX('Promo Calendar'!$F$6:$F$400,MATCH($A7,'Promo Calendar'!$O$6:$O$400,0))&IF(COUNTIFS('Promo Calendar'!$A$6:$A$400,$A7,'Promo Calendar'!$L$6:$L$400,"Active")>1," (+"&(COUNTIFS('Promo Calendar'!$A$6:$A$400,$A7,'Promo Calendar'!$L$6:$L$400,"Active")-1)&" more)",""))) | P7: =IF($A7="","",IF(COUNTIFS('Promo Calendar'!$A$6:$A$400,$A7,'Promo Calendar'!$L$6:$L$400,"Active",'Promo Calendar'!$G$6:$G$400,">0")>0,_xlfn.MINIFS('Promo Calendar'!$G$6:$G$400,'Promo Calendar'!$A$6:$A$400,$A7,'Promo Calendar'!$L$6:$L$400,"Active",'Promo Calendar'!$G$6:$G$400,">0"),IF(M7="","Not set",M7))) | Q7: =IF($A7="","",IF(COUNTIFS('Promo Calendar'!$A$6:$A$400,$A7,'Promo Calendar'!$I$6:$I$400,">"&TODAY())=0,"None scheduled",_xlfn.MINIFS('Promo Calendar'!$I$6:$I$400,'Promo Calendar'!$A$6:$A$400,$A7,'Promo Calendar'!$I$6:$I$400,">"&TODAY()))) | R7: Promote ZOA at 2 for $4. | T7: Non-Alc Chain 9/8/26 | U7: Current (2026) | W7: =IF($A7="","",COUNTIFS('Visit Log'!$C$6:$C$1005,$A7,'Visit Log'!$A$6:$A$1005,">="&TODAY()-30)) | X7: =IF($A7="","",COUNTIFS('Visit Log'!$C$6:$C$1005,$A7,'Visit Log'!$T$6:$T$1005,"Open")+COUNTIFS('Visit Log'!$C$6:$C$1005,$A7,'Visit Log'!$T$6:$T$1005,"In Progress")) | Y7: =IF($A7="","",IF(COUNTIFS('Visit Log'!$C$6:$C$1005,$A7)=0,"No visits",_xlfn.MAXIFS('Visit Log'!$A$6:$A$1005,'Visit Log'!$C$6:$C$1005,$A7)))
A8: ZOA | Southwest Division (SWD) | B8: ZOA | C8: Albertsons/Safeway | D8: Southwest Division (SWD) | E8: AZ / LV / NM | H8: ZOA core SKUs | J8: Promo display where authorized | L8: Promo 2 for $4 | N8: Aug-Dec 2026 | O8: =IF($A8="","",IF(COUNTIFS('Promo Calendar'!$A$6:$A$400,$A8,'Promo Calendar'!$L$6:$L$400,"Active")=0,"None active",INDEX('Promo Calendar'!$F$6:$F$400,MATCH($A8,'Promo Calendar'!$O$6:$O$400,0))&IF(COUNTIFS('Promo Calendar'!$A$6:$A$400,$A8,'Promo Calendar'!$L$6:$L$400,"Active")>1," (+"&(COUNTIFS('Promo Calendar'!$A$6:$A$400,$A8,'Promo Calendar'!$L$6:$L$400,"Active")-1)&" more)",""))) | P8: =IF($A8="","",IF(COUNTIFS('Promo Calendar'!$A$6:$A$400,$A8,'Promo Calendar'!$L$6:$L$400,"Active",'Promo Calendar'!$G$6:$G$400,">0")>0,_xlfn.MINIFS('Promo Calendar'!$G$6:$G$400,'Promo Calendar'!$A$6:$A$400,$A8,'Promo Calendar'!$L$6:$L$400,"Active",'Promo Calendar'!$G$6:$G$400,">0"),IF(M8="","Not set",M8))) | Q8: =IF($A8="","",IF(COUNTIFS('Promo Calendar'!$A$6:$A$400,$A8,'Promo Calendar'!$I$6:$I$400,">"&TODAY())=0,"None scheduled",_xlfn.MINIFS('Promo Calendar'!$I$6:$I$400,'Promo Calendar'!$A$6:$A$400,$A8,'Promo Calendar'!$I$6:$I$400,">"&TODAY()))) | R8: Promote ZOA at 2 for $4. | T8: Non-Alc Chain 9/8/26 | U8: Current (2026) | W8: =IF($A8="","",COUNTIFS('Visit Log'!$C$6:$C$1005,$A8,'Visit Log'!$A$6:$A$1005,">="&TODAY()-30)) | X8: =IF($A8="","",COUNTIFS('Visit Log'!$C$6:$C$1005,$A8,'Visit Log'!$T$6:$T$1005,"Open")+COUNTIFS('Visit Log'!$C$6:$C$1005,$A8,'Visit Log'!$T$6:$T$1005,"In Progress")) | Y8: =IF($A8="","",IF(COUNTIFS('Visit Log'!$C$6:$C$1005,$A8)=0,"No visits",_xlfn.MAXIFS('Visit Log'!$A$6:$A$1005,'Visit Log'!$C$6:$C$1005,$A8)))
A9: ZOA | Smart & Final | B9: ZOA | C9: Smart & Final | D9: Smart & Final | E9: Chain-wide | H9: 12-pack; Frosted Grape and Tropical Punch singles | J9: Store-level display (authorization required); shelf tags | L9: 12pk $17.99 (to 9/22); singles 2 for $3 (9/23-11/3) | N9: 8/26-11/3/2026 | O9: =IF($A9="","",IF(COUNTIFS('Promo Calendar'!$A$6:$A$400,$A9,'Promo Calendar'!$L$6:$L$400,"Active")=0,"None active",INDEX('Promo Calendar'!$F$6:$F$400,MATCH($A9,'Promo Calendar'!$O$6:$O$400,0))&IF(COUNTIFS('Promo Calendar'!$A$6:$A$400,$A9,'Promo Calendar'!$L$6:$L$400,"Active")>1," (+"&(COUNTIFS('Promo Calendar'!$A$6:$A$400,$A9,'Promo Calendar'!$L$6:$L$400,"Active")-1)&" more)",""))) | P9: =IF($A9="","",IF(COUNTIFS('Promo Calendar'!$A$6:$A$400,$A9,'Promo Calendar'!$L$6:$L$400,"Active",'Promo Calendar'!$G$6:$G$400,">0")>0,_xlfn.MINIFS('Promo Calendar'!$G$6:$G$400,'Promo Calendar'!$A$6:$A$400,$A9,'Promo Calendar'!$L$6:$L$400,"Active",'Promo Calendar'!$G$6:$G$400,">0"),IF(M9="","Not set",M9))) | Q9: =IF($A9="","",IF(COUNTIFS('Promo Calendar'!$A$6:$A$400,$A9,'Promo Calendar'!$I$6:$I$400,">"&TODAY())=0,"None scheduled",_xlfn.MINIFS('Promo Calendar'!$I$6:$I$400,'Promo Calendar'!$A$6:$A$400,$A9,'Promo Calendar'!$I$6:$I$400,">"&TODAY()))) | R9: Secure shelf tags and store-level display authorization. | T9: Non-Alc Chain 9/8/26 | U9: Current (2026) | W9: =IF($A9="","",COUNTIFS('Visit Log'!$C$6:$C$1005,$A9,'Visit Log'!$A$6:$A$1005,">="&TODAY()-30)) | X9: =IF($A9="","",COUNTIFS('Visit Log'!$C$6:$C$1005,$A9,'Visit Log'!$T$6:$T$1005,"Open")+COUNTIFS('Visit Log'!$C$6:$C$1005,$A9,'Visit Log'!$T$6:$T$1005,"In Progress")) | Y9: =IF($A9="","",IF(COUNTIFS('Visit Log'!$C$6:$C$1005,$A9)=0,"No visits",_xlfn.MAXIFS('Visit Log'!$A$6:$A$1005,'Visit Log'!$C$6:$C$1005,$A9)))
A10: ZOA | Yoke's Fresh Market | B10: ZOA | C10: Yoke's Fresh Market | D10: Yoke's Fresh Market | E10: W. WA | H10: ZOA core SKUs | J10: Per store planogram - confirm | K10: $15.30 case cost | L10: Retail TBD | N10: 8/2-10/3/2026 | O10: =IF($A10="","",IF(COUNTIFS('Promo Calendar'!$A$6:$A$400,$A10,'Promo Calendar'!$L$6:$L$400,"Active")=0,"None active",INDEX('Promo Calendar'!$F$6:$F$400,MATCH($A10,'Promo Calendar'!$O$6:$O$400,0))&IF(COUNTIFS('Promo Calendar'!$A$6:$A$400,$A10,'Promo Calendar'!$L$6:$L$400,"Active")>1," (+"&(COUNTIFS('Promo Calendar'!$A$6:$A$400,$A10,'Promo Calendar'!$L$6:$L$400,"Active")-1)&" more)",""))) | P10: =IF($A10="","",IF(COUNTIFS('Promo Calendar'!$A$6:$A$400,$A10,'Promo Calendar'!$L$6:$L$400,"Active",'Promo Calendar'!$G$6:$G$400,">0")>0,_xlfn.MINIFS('Promo Calendar'!$G$6:$G$400,'Promo Calendar'!$A$6:$A$400,$A10,'Promo Calendar'!$L$6:$L$400,"Active",'Promo Calendar'!$G$6:$G$400,">0"),IF(M10="","Not set",M10))) | Q10: =IF($A10="","",IF(COUNTIFS('Promo Calendar'!$A$6:$A$400,$A10,'Promo Calendar'!$I$6:$I$400,">"&TODAY())=0,"None scheduled",_xlfn.MINIFS('Promo Calendar'!$I$6:$I$400,'Promo Calendar'!$A$6:$A$400,$A10,'Promo Calendar'!$I$6:$I$400,">"&TODAY()))) | R10: $15.30 case cost. Retail TBD. | T10: Non-Alc Chain 9/8/26 | U10: Current (2026) | W10: =IF($A10="","",COUNTIFS('Visit Log'!$C$6:$C$1005,$A10,'Visit Log'!$A$6:$A$1005,">="&TODAY()-30)) | X10: =IF($A10="","",COUNTIFS('Visit Log'!$C$6:$C$1005,$A10,'Visit Log'!$T$6:$T$1005,"Open")+COUNTIFS('Visit Log'!$C$6:$C$1005,$A10,'Visit Log'!$T$6:$T$1005,"In Progress")) | Y10: =IF($A10="","",IF(COUNTIFS('Visit Log'!$C$6:$C$1005,$A10)=0,"No visits",_xlfn.MAXIFS('Visit Log'!$A$6:$A$1005,'Visit Log'!$C$6:$C$1005,$A10)))
A11: Henry's | Mountain West North | B11: Henry's | C11: Albertsons/Safeway | D11: Mountain West North | E11: PNW / ID / UT / WY | H11: Root Beer, Orange Cream, Vanilla Cream; Black Cherry Cream select stores | I11: 1 case of each flavor backstock | J11: Shelf set + displays | K11: $23 case (transition) | L11: SRP $7.99 (2025 ABSCO) | M11: 7.99 | N11: Effective 9/7/2026 | O11: =IF($A11="","",IF(COUNTIFS('Promo Calendar'!$A$6:$A$400,$A11,'Promo Calendar'!$L$6:$L$400,"Active")=0,"None active",INDEX('Promo Calendar'!$F$6:$F$400,MATCH($A11,'Promo Calendar'!$O$6:$O$400,0))&IF(COUNTIFS('Promo Calendar'!$A$6:$A$400,$A11,'Promo Calendar'!$L$6:$L$400,"Active")>1," (+"&(COUNTIFS('Promo Calendar'!$A$6:$A$400,$A11,'Promo Calendar'!$L$6:$L$400,"Active")-1)&" more)",""))) | P11: =IF($A11="","",IF(COUNTIFS('Promo Calendar'!$A$6:$A$400,$A11,'Promo Calendar'!$L$6:$L$400,"Active",'Promo Calendar'!$G$6:$G$400,">0")>0,_xlfn.MINIFS('Promo Calendar'!$G$6:$G$400,'Promo Calendar'!$A$6:$A$400,$A11,'Promo Calendar'!$L$6:$L$400,"Active",'Promo Calendar'!$G$6:$G$400,">0"),IF(M11="","Not set",M11))) | Q11: =IF($A11="","",IF(COUNTIFS('Promo Calendar'!$A$6:$A$400,$A11,'Promo Calendar'!$I$6:$I$400,">"&TODAY())=0,"None scheduled",_xlfn.MINIFS('Promo Calendar'!$I$6:$I$400,'Promo Calendar'!$A$6:$A$400,$A11,'Promo Calendar'!$I$6:$I$400,">"&TODAY()))) | R11: Reflect approved PTRs in distributor price books. Sell in displays. Transition to $23 case pricing. | T11: Non-Alc 9/8/26 + HW 8/25/25 | U11: Confirm for 2026 | W11: =IF($A11="","",COUNTIFS('Visit Log'!$C$6:$C$1005,$A11,'Visit Log'!$A$6:$A$1005,">="&TODAY()-30)) | X11: =IF($A11="","",COUNTIFS('Visit Log'!$C$6:$C$1005,$A11,'Visit Log'!$T$6:$T$1005,"Open")+COUNTIFS('Visit Log'!$C$6:$C$1005,$A11,'Visit Log'!$T$6:$T$1005,"In Progress")) | Y11: =IF($A11="","",IF(COUNTIFS('Visit Log'!$C$6:$C$1005,$A11)=0,"No visits",_xlfn.MAXIFS('Visit Log'!$A$6:$A$1005,'Visit Log'!$C$6:$C$1005,$A11)))
A12: Henry's | Mountain West South | B12: Henry's | C12: Albertsons/Safeway | D12: Mountain West South | E12: CO / WY | H12: Root Beer, Orange Cream, Vanilla Cream; Black Cherry Cream select stores | I12: 1 case of each flavor backstock | J12: Shelf set + displays | K12: New pricing structure | L12: SRP $7.99 (2025 ABSCO) | M12: 7.99 | N12: Effective 9/7/2026 | O12: =IF($A12="","",IF(COUNTIFS('Promo Calendar'!$A$6:$A$400,$A12,'Promo Calendar'!$L$6:$L$400,"Active")=0,"None active",INDEX('Promo Calendar'!$F$6:$F$400,MATCH($A12,'Promo Calendar'!$O$6:$O$400,0))&IF(COUNTIFS('Promo Calendar'!$A$6:$A$400,$A12,'Promo Calendar'!$L$6:$L$400,"Active")>1," (+"&(COUNTIFS('Promo Calendar'!$A$6:$A$400,$A12,'Promo Calendar'!$L$6:$L$400,"Active")-1)&" more)",""))) | P12: =IF($A12="","",IF(COUNTIFS('Promo Calendar'!$A$6:$A$400,$A12,'Promo Calendar'!$L$6:$L$400,"Active",'Promo Calendar'!$G$6:$G$400,">0")>0,_xlfn.MINIFS('Promo Calendar'!$G$6:$G$400,'Promo Calendar'!$A$6:$A$400,$A12,'Promo Calendar'!$L$6:$L$400,"Active",'Promo Calendar'!$G$6:$G$400,">0"),IF(M12="","Not set",M12))) | Q12: =IF($A12="","",IF(COUNTIFS('Promo Calendar'!$A$6:$A$400,$A12,'Promo Calendar'!$I$6:$I$400,">"&TODAY())=0,"None scheduled",_xlfn.MINIFS('Promo Calendar'!$I$6:$I$400,'Promo Calendar'!$A$6:$A$400,$A12,'Promo Calendar'!$I$6:$I$400,">"&TODAY()))) | R12: Confirm distributor price book accuracy. Sell in displays. Execute the new pricing structure. | T12: Non-Alc 9/8/26 + HW 8/25/25 | U12: Confirm for 2026 | W12: =IF($A12="","",COUNTIFS('Visit Log'!$C$6:$C$1005,$A12,'Visit Log'!$A$6:$A$1005,">="&TODAY()-30)) | X12: =IF($A12="","",COUNTIFS('Visit Log'!$C$6:$C$1005,$A12,'Visit Log'!$T$6:$T$1005,"Open")+COUNTIFS('Visit Log'!$C$6:$C$1005,$A12,'Visit Log'!$T$6:$T$1005,"In Progress")) | Y12: =IF($A12="","",IF(COUNTIFS('Visit Log'!$C$6:$C$1005,$A12)=0,"No visits",_xlfn.MAXIFS('Visit Log'!$A$6:$A$1005,'Visit Log'!$C$6:$C$1005,$A12)))
A13: Henry's | Southwest Division (SWD) #17 | B13: Henry's | C13: Albertsons/Safeway | D13: Southwest Division (SWD) #17 | E13: AZ / LV / NM | H13: Root Beer, Orange Cream, Vanilla Cream; Black Cherry Cream select stores | I13: 1 case of each flavor backstock | J13: Shelf set + displays | L13: EDLP $7.99 | M13: 7.99 | N13: Ongoing | O13: =IF($A13="","",IF(COUNTIFS('Promo Calendar'!$A$6:$A$400,$A13,'Promo Calendar'!$L$6:$L$400,"Active")=0,"None active",INDEX('Promo Calendar'!$F$6:$F$400,MATCH($A13,'Promo Calendar'!$O$6:$O$400,0))&IF(COUNTIFS('Promo Calendar'!$A$6:$A$400,$A13,'Promo Calendar'!$L$6:$L$400,"Active")>1," (+"&(COUNTIFS('Promo Calendar'!$A$6:$A$400,$A13,'Promo Calendar'!$L$6:$L$400,"Active")-1)&" more)",""))) | P13: =IF($A13="","",IF(COUNTIFS('Promo Calendar'!$A$6:$A$400,$A13,'Promo Calendar'!$L$6:$L$400,"Active",'Promo Calendar'!$G$6:$G$400,">0")>0,_xlfn.MINIFS('Promo Calendar'!$G$6:$G$400,'Promo Calendar'!$A$6:$A$400,$A13,'Promo Calendar'!$L$6:$L$400,"Active",'Promo Calendar'!$G$6:$G$400,">0"),IF(M13="","Not set",M13))) | Q13: =IF($A13="","",IF(COUNTIFS('Promo Calendar'!$A$6:$A$400,$A13,'Promo Calendar'!$I$6:$I$400,">"&TODAY())=0,"None scheduled",_xlfn.MINIFS('Promo Calendar'!$I$6:$I$400,'Promo Calendar'!$A$6:$A$400,$A13,'Promo Calendar'!$I$6:$I$400,">"&TODAY()))) | R13: Reflect approved PTRs, actively sell displays and maintain $7.99 EDLP. | T13: Non-Alc 9/8/26 + HW 8/25/25 | U13: Current (2026) | W13: =IF($A13="","",COUNTIFS('Visit Log'!$C$6:$C$1005,$A13,'Visit Log'!$A$6:$A$1005,">="&TODAY()-30)) | X13: =IF($A13="","",COUNTIFS('Visit Log'!$C$6:$C$1005,$A13,'Visit Log'!$T$6:$T$1005,"Open")+COUNTIFS('Visit Log'!$C$6:$C$1005,$A13,'Visit Log'!$T$6:$T$1005,"In Progress")) | Y13: =IF($A13="","",IF(COUNTIFS('Visit Log'!$C$6:$C$1005,$A13)=0,"No visits",_xlfn.MAXIFS('Visit Log'!$A$6:$A$1005,'Visit Log'!$C$6:$C$1005,$A13)))
A14: Henry's | BevMo! | B14: Henry's | C14: BevMo! | D14: BevMo! | E14: Non-alcohol section | F14: MU-AK ID OR WA: 5; MU-AZ NM LAS VEGAS: 5; MU-CA HI NORTH NV: 99 | G14: 109 | H14: Root Beer, Black Cherry Cream, Orange Cream, Vanilla Cream | I14: 1 case of each flavor backstock | J14: Non-alcohol section | L14: SRP $8.99; promo TBD | M14: 8.99 | N14: Ongoing | O14: =IF($A14="","",IF(COUNTIFS('Promo Calendar'!$A$6:$A$400,$A14,'Promo Calendar'!$L$6:$L$400,"Active")=0,"None active",INDEX('Promo Calendar'!$F$6:$F$400,MATCH($A14,'Promo Calendar'!$O$6:$O$400,0))&IF(COUNTIFS('Promo Calendar'!$A$6:$A$400,$A14,'Promo Calendar'!$L$6:$L$400,"Active")>1," (+"&(COUNTIFS('Promo Calendar'!$A$6:$A$400,$A14,'Promo Calendar'!$L$6:$L$400,"Active")-1)&" more)",""))) | P14: =IF($A14="","",IF(COUNTIFS('Promo Calendar'!$A$6:$A$400,$A14,'Promo Calendar'!$L$6:$L$400,"Active",'Promo Calendar'!$G$6:$G$400,">0")>0,_xlfn.MINIFS('Promo Calendar'!$G$6:$G$400,'Promo Calendar'!$A$6:$A$400,$A14,'Promo Calendar'!$L$6:$L$400,"Active",'Promo Calendar'!$G$6:$G$400,">0"),IF(M14="","Not set",M14))) | Q14: =IF($A14="","",IF(COUNTIFS('Promo Calendar'!$A$6:$A$400,$A14,'Promo Calendar'!$I$6:$I$400,">"&TODAY())=0,"None scheduled",_xlfn.MINIFS('Promo Calendar'!$I$6:$I$400,'Promo Calendar'!$A$6:$A$400,$A14,'Promo Calendar'!$I$6:$I$400,">"&TODAY()))) | R14: Confirm all four Henry's SKUs are on shelf. Support reorders and in-stock conditions. Promo pricing TBD (Bob and Lexi setting up price promotions, per 2025 hot sheet). | T14: Non-Alc 9/8/26 + HW 8/25/25 | U14: Current (2026) | W14: =IF($A14="","",COUNTIFS('Visit Log'!$C$6:$C$1005,$A14,'Visit Log'!$A$6:$A$1005,">="&TODAY()-30)) | X14: =IF($A14="","",COUNTIFS('Visit Log'!$C$6:$C$1005,$A14,'Visit Log'!$T$6:$T$1005,"Open")+COUNTIFS('Visit Log'!$C$6:$C$1005,$A14,'Visit Log'!$T$6:$T$1005,"In Progress")) | Y14: =IF($A14="","",IF(COUNTIFS('Visit Log'!$C$6:$C$1005,$A14)=0,"No visits",_xlfn.MAXIFS('Visit Log'!$A$6:$A$1005,'Visit Log'!$C$6:$C$1005,$A14)))
A15: Henry's | Raley's | B15: Henry's | C15: Raley's | D15: Raley's | E15: NorCal (+ AZ per 2025 hot sheet) | F15: MU-CA HI NORTH NV: 115; MU-AZ NM LAS VEGAS: 44 | G15: 159 | H15: Root Beer, Orange Cream, Vanilla Cream; Black Cherry Cream select stores | I15: 1 case of each flavor backstock | J15: Shelf set + displays | K15: $23 frontline; $3.45 O/I; $19.55 net; $1.00/CE scan | L15: SRP $6.49 (2025) | M15: 6.49 | N15: 2H 2026 - four promo windows (dates not listed) | O15: =IF($A15="","",IF(COUNTIFS('Promo Calendar'!$A$6:$A$400,$A15,'Promo Calendar'!$L$6:$L$400,"Active")=0,"None active",INDEX('Promo Calendar'!$F$6:$F$400,MATCH($A15,'Promo Calendar'!$O$6:$O$400,0))&IF(COUNTIFS('Promo Calendar'!$A$6:$A$400,$A15,'Promo Calendar'!$L$6:$L$400,"Active")>1," (+"&(COUNTIFS('Promo Calendar'!$A$6:$A$400,$A15,'Promo Calendar'!$L$6:$L$400,"Active")-1)&" more)",""))) | P15: =IF($A15="","",IF(COUNTIFS('Promo Calendar'!$A$6:$A$400,$A15,'Promo Calendar'!$L$6:$L$400,"Active",'Promo Calendar'!$G$6:$G$400,">0")>0,_xlfn.MINIFS('Promo Calendar'!$G$6:$G$400,'Promo Calendar'!$A$6:$A$400,$A15,'Promo Calendar'!$L$6:$L$400,"Active",'Promo Calendar'!$G$6:$G$400,">0"),IF(M15="","Not set",M15))) | Q15: =IF($A15="","",IF(COUNTIFS('Promo Calendar'!$A$6:$A$400,$A15,'Promo Calendar'!$I$6:$I$400,">"&TODAY())=0,"None scheduled",_xlfn.MINIFS('Promo Calendar'!$I$6:$I$400,'Promo Calendar'!$A$6:$A$400,$A15,'Promo Calendar'!$I$6:$I$400,">"&TODAY()))) | R15: $23 frontline. $3.45 O/I, $19.55 net and $1.00/CE scan in four promotional windows. Priority to close gaps and hit 90%+ re-service rates. | T15: Non-Alc 9/8/26 + HW 8/25/25 | U15: Confirm for 2026 | W15: =IF($A15="","",COUNTIFS('Visit Log'!$C$6:$C$1005,$A15,'Visit Log'!$A$6:$A$1005,">="&TODAY()-30)) | X15: =IF($A15="","",COUNTIFS('Visit Log'!$C$6:$C$1005,$A15,'Visit Log'!$T$6:$T$1005,"Open")+COUNTIFS('Visit Log'!$C$6:$C$1005,$A15,'Visit Log'!$T$6:$T$1005,"In Progress")) | Y15: =IF($A15="","",IF(COUNTIFS('Visit Log'!$C$6:$C$1005,$A15)=0,"No visits",_xlfn.MAXIFS('Visit Log'!$A$6:$A$1005,'Visit Log'!$C$6:$C$1005,$A15)))
A16: Henry's | Yoke's Fresh Market | B16: Henry's | C16: Yoke's Fresh Market | D16: Yoke's Fresh Market | E16: W. WA | F16: MU-AK ID OR WA: 17 | G16: 17 | H16: Root Beer, Black Cherry Cream, Orange Cream, Vanilla Cream | I16: 1 case of each flavor backstock | J16: Shelf set + displays | K16: $19.55 case cost (6/1-9/8/2026) | L16: SRP $6.49 (2025); retail TBD | M16: 6.49 | N16: 6/1-9/8/2026 | O16: =IF($A16="","",IF(COUNTIFS('Promo Calendar'!$A$6:$A$400,$A16,'Promo Calendar'!$L$6:$L$400,"Active")=0,"None active",INDEX('Promo Calendar'!$F$6:$F$400,MATCH($A16,'Promo Calendar'!$O$6:$O$400,0))&IF(COUNTIFS('Promo Calendar'!$A$6:$A$400,$A16,'Promo Calendar'!$L$6:$L$400,"Active")>1," (+"&(COUNTIFS('Promo Calendar'!$A$6:$A$400,$A16,'Promo Calendar'!$L$6:$L$400,"Active")-1)&" more)",""))) | P16: =IF($A16="","",IF(COUNTIFS('Promo Calendar'!$A$6:$A$400,$A16,'Promo Calendar'!$L$6:$L$400,"Active",'Promo Calendar'!$G$6:$G$400,">0")>0,_xlfn.MINIFS('Promo Calendar'!$G$6:$G$400,'Promo Calendar'!$A$6:$A$400,$A16,'Promo Calendar'!$L$6:$L$400,"Active",'Promo Calendar'!$G$6:$G$400,">0"),IF(M16="","Not set",M16))) | Q16: =IF($A16="","",IF(COUNTIFS('Promo Calendar'!$A$6:$A$400,$A16,'Promo Calendar'!$I$6:$I$400,">"&TODAY())=0,"None scheduled",_xlfn.MINIFS('Promo Calendar'!$I$6:$I$400,'Promo Calendar'!$A$6:$A$400,$A16,'Promo Calendar'!$I$6:$I$400,">"&TODAY()))) | R16: $19.55 case cost. Retail TBD. Priority to close gaps and hit 90%+ re-service rates. Sell in displays at store level to support promotional pricing. | T16: Non-Alc 9/8/26 + HW 8/25/25 | U16: Confirm for 2026 | W16: =IF($A16="","",COUNTIFS('Visit Log'!$C$6:$C$1005,$A16,'Visit Log'!$A$6:$A$1005,">="&TODAY()-30)) | X16: =IF($A16="","",COUNTIFS('Visit Log'!$C$6:$C$1005,$A16,'Visit Log'!$T$6:$T$1005,"Open")+COUNTIFS('Visit Log'!$C$6:$C$1005,$A16,'Visit Log'!$T$6:$T$1005,"In Progress")) | Y16: =IF($A16="","",IF(COUNTIFS('Visit Log'!$C$6:$C$1005,$A16)=0,"No visits",_xlfn.MAXIFS('Visit Log'!$A$6:$A$1005,'Visit Log'!$C$6:$C$1005,$A16)))
A17: Henry's | WinCo Foods | B17: Henry's | C17: WinCo Foods | D17: WinCo Foods | E17: PNW / NorCal / Utah | F17: MU-AK ID OR WA: 59; MU-AZ NM LAS VEGAS: 10; MU-CA HI NORTH NV: 40 | G17: 109 | H17: Root Beer, Black Cherry Cream, Orange Cream, Vanilla Cream | I17: 1 case of each flavor backstock | J17: Shelf set + promo displays | K17: $23 frontline; $19.55 Tier 2; $18.40 Tier 3 | L17: SRP $6.49 (2025) | M17: 6.49 | N17: Jun-Dec 2026 (see Promo Calendar) | O17: =IF($A17="","",IF(COUNTIFS('Promo Calendar'!$A$6:$A$400,$A17,'Promo Calendar'!$L$6:$L$400,"Active")=0,"None active",INDEX('Promo Calendar'!$F$6:$F$400,MATCH($A17,'Promo Calendar'!$O$6:$O$400,0))&IF(COUNTIFS('Promo Calendar'!$A$6:$A$400,$A17,'Promo Calendar'!$L$6:$L$400,"Active")>1," (+"&(COUNTIFS('Promo Calendar'!$A$6:$A$400,$A17,'Promo Calendar'!$L$6:$L$400,"Active")-1)&" more)",""))) | P17: =IF($A17="","",IF(COUNTIFS('Promo Calendar'!$A$6:$A$400,$A17,'Promo Calendar'!$L$6:$L$400,"Active",'Promo Calendar'!$G$6:$G$400,">0")>0,_xlfn.MINIFS('Promo Calendar'!$G$6:$G$400,'Promo Calendar'!$A$6:$A$400,$A17,'Promo Calendar'!$L$6:$L$400,"Active",'Promo Calendar'!$G$6:$G$400,">0"),IF(M17="","Not set",M17))) | Q17: =IF($A17="","",IF(COUNTIFS('Promo Calendar'!$A$6:$A$400,$A17,'Promo Calendar'!$I$6:$I$400,">"&TODAY())=0,"None scheduled",_xlfn.MINIFS('Promo Calendar'!$I$6:$I$400,'Promo Calendar'!$A$6:$A$400,$A17,'Promo Calendar'!$I$6:$I$400,">"&TODAY()))) | R17: $23 frontline effective 6/1. $19.55 Tier 2 and $18.40 Tier 3 promotional/display pricing. Priority to close gaps and hit 90%+ re-service rates. | T17: Non-Alc 9/8/26 + HW 8/25/25 | U17: Confirm for 2026 | W17: =IF($A17="","",COUNTIFS('Visit Log'!$C$6:$C$1005,$A17,'Visit Log'!$A$6:$A$1005,">="&TODAY()-30)) | X17: =IF($A17="","",COUNTIFS('Visit Log'!$C$6:$C$1005,$A17,'Visit Log'!$T$6:$T$1005,"Open")+COUNTIFS('Visit Log'!$C$6:$C$1005,$A17,'Visit Log'!$T$6:$T$1005,"In Progress")) | Y17: =IF($A17="","",IF(COUNTIFS('Visit Log'!$C$6:$C$1005,$A17)=0,"No visits",_xlfn.MAXIFS('Visit Log'!$A$6:$A$1005,'Visit Log'!$C$6:$C$1005,$A17)))
A18: Henry's | Save Mart / Lucky | B18: Henry's | C18: Save Mart / Lucky | D18: Save Mart / Lucky | E18: NorCal / N. NV | F18: MU-CA HI NORTH NV: 188 | G18: 188 | H18: Root Beer, Orange Cream, Vanilla Cream; Black Cherry Cream select stores | I18: 1 case of each flavor backstock | J18: Shelf set + displays | L18: SRP $6.49 | M18: 6.49 | N18: 2025: 6/1-9/6, 10/5-1/3 | O18: =IF($A18="","",IF(COUNTIFS('Promo Calendar'!$A$6:$A$400,$A18,'Promo Calendar'!$L$6:$L$400,"Active")=0,"None active",INDEX('Promo Calendar'!$F$6:$F$400,MATCH($A18,'Promo Calendar'!$O$6:$O$400,0))&IF(COUNTIFS('Promo Calendar'!$A$6:$A$400,$A18,'Promo Calendar'!$L$6:$L$400,"Active")>1," (+"&(COUNTIFS('Promo Calendar'!$A$6:$A$400,$A18,'Promo Calendar'!$L$6:$L$400,"Active")-1)&" more)",""))) | P18: =IF($A18="","",IF(COUNTIFS('Promo Calendar'!$A$6:$A$400,$A18,'Promo Calendar'!$L$6:$L$400,"Active",'Promo Calendar'!$G$6:$G$400,">0")>0,_xlfn.MINIFS('Promo Calendar'!$G$6:$G$400,'Promo Calendar'!$A$6:$A$400,$A18,'Promo Calendar'!$L$6:$L$400,"Active",'Promo Calendar'!$G$6:$G$400,">0"),IF(M18="","Not set",M18))) | Q18: =IF($A18="","",IF(COUNTIFS('Promo Calendar'!$A$6:$A$400,$A18,'Promo Calendar'!$I$6:$I$400,">"&TODAY())=0,"None scheduled",_xlfn.MINIFS('Promo Calendar'!$I$6:$I$400,'Promo Calendar'!$A$6:$A$400,$A18,'Promo Calendar'!$I$6:$I$400,">"&TODAY()))) | R18: Priority to close gaps and hit 90%+ re-service rates. Sell in displays at store level to support promotional pricing. | T18: HW Hot Sheet 8/25/25 | U18: Confirm for 2026 | W18: =IF($A18="","",COUNTIFS('Visit Log'!$C$6:$C$1005,$A18,'Visit Log'!$A$6:$A$1005,">="&TODAY()-30)) | X18: =IF($A18="","",COUNTIFS('Visit Log'!$C$6:$C$1005,$A18,'Visit Log'!$T$6:$T$1005,"Open")+COUNTIFS('Visit Log'!$C$6:$C$1005,$A18,'Visit Log'!$T$6:$T$1005,"In Progress")) | Y18: =IF($A18="","",IF(COUNTIFS('Visit Log'!$C$6:$C$1005,$A18)=0,"No visits",_xlfn.MAXIFS('Visit Log'!$A$6:$A$1005,'Visit Log'!$C$6:$C$1005,$A18)))
A19: Henry's | SFWY Portland Div. #19 | B19: Henry's | C19: Albertsons/Safeway | D19: SFWY Portland Div. #19 | E19: OR / SW WA | H19: Root Beer, Orange Cream, Vanilla Cream; Black Cherry Cream select stores | I19: 1 case of each flavor backstock | J19: Shelves merchandised; backstock | L19: SRP $7.99 | M19: 7.99 | N19: 2025: 6/1-9/6, 10/5-1/3 | O19: =IF($A19="","",IF(COUNTIFS('Promo Calendar'!$A$6:$A$400,$A19,'Promo Calendar'!$L$6:$L$400,"Active")=0,"None active",INDEX('Promo Calendar'!$F$6:$F$400,MATCH($A19,'Promo Calendar'!$O$6:$O$400,0))&IF(COUNTIFS('Promo Calendar'!$A$6:$A$400,$A19,'Promo Calendar'!$L$6:$L$400,"Active")>1," (+"&(COUNTIFS('Promo Calendar'!$A$6:$A$400,$A19,'Promo Calendar'!$L$6:$L$400,"Active")-1)&" more)",""))) | P19: =IF($A19="","",IF(COUNTIFS('Promo Calendar'!$A$6:$A$400,$A19,'Promo Calendar'!$L$6:$L$400,"Active",'Promo Calendar'!$G$6:$G$400,">0")>0,_xlfn.MINIFS('Promo Calendar'!$G$6:$G$400,'Promo Calendar'!$A$6:$A$400,$A19,'Promo Calendar'!$L$6:$L$400,"Active",'Promo Calendar'!$G$6:$G$400,">0"),IF(M19="","Not set",M19))) | Q19: =IF($A19="","",IF(COUNTIFS('Promo Calendar'!$A$6:$A$400,$A19,'Promo Calendar'!$I$6:$I$400,">"&TODAY())=0,"None scheduled",_xlfn.MINIFS('Promo Calendar'!$I$6:$I$400,'Promo Calendar'!$A$6:$A$400,$A19,'Promo Calendar'!$I$6:$I$400,">"&TODAY()))) | R19: Ensure shelves are merchandised. Sufficient inventory in backstock. | T19: HW Hot Sheet 8/25/25 | U19: Confirm for 2026 | W19: =IF($A19="","",COUNTIFS('Visit Log'!$C$6:$C$1005,$A19,'Visit Log'!$A$6:$A$1005,">="&TODAY()-30)) | X19: =IF($A19="","",COUNTIFS('Visit Log'!$C$6:$C$1005,$A19,'Visit Log'!$T$6:$T$1005,"Open")+COUNTIFS('Visit Log'!$C$6:$C$1005,$A19,'Visit Log'!$T$6:$T$1005,"In Progress")) | Y19: =IF($A19="","",IF(COUNTIFS('Visit Log'!$C$6:$C$1005,$A19)=0,"No visits",_xlfn.MAXIFS('Visit Log'!$A$6:$A$1005,'Visit Log'!$C$6:$C$1005,$A19)))
A20: Henry's | Haggen Div. #24 | B20: Henry's | C20: Albertsons/Safeway | D20: Haggen Div. #24 | E20: W. WA | H20: Root Beer, Orange Cream, Vanilla Cream; Black Cherry Cream select stores | I20: 1 case of each flavor backstock | J20: Shelves merchandised; backstock | L20: SRP $7.99 | M20: 7.99 | N20: 2025: 6/1-9/6, 10/5-1/3 | O20: =IF($A20="","",IF(COUNTIFS('Promo Calendar'!$A$6:$A$400,$A20,'Promo Calendar'!$L$6:$L$400,"Active")=0,"None active",INDEX('Promo Calendar'!$F$6:$F$400,MATCH($A20,'Promo Calendar'!$O$6:$O$400,0))&IF(COUNTIFS('Promo Calendar'!$A$6:$A$400,$A20,'Promo Calendar'!$L$6:$L$400,"Active")>1," (+"&(COUNTIFS('Promo Calendar'!$A$6:$A$400,$A20,'Promo Calendar'!$L$6:$L$400,"Active")-1)&" more)",""))) | P20: =IF($A20="","",IF(COUNTIFS('Promo Calendar'!$A$6:$A$400,$A20,'Promo Calendar'!$L$6:$L$400,"Active",'Promo Calendar'!$G$6:$G$400,">0")>0,_xlfn.MINIFS('Promo Calendar'!$G$6:$G$400,'Promo Calendar'!$A$6:$A$400,$A20,'Promo Calendar'!$L$6:$L$400,"Active",'Promo Calendar'!$G$6:$G$400,">0"),IF(M20="","Not set",M20))) | Q20: =IF($A20="","",IF(COUNTIFS('Promo Calendar'!$A$6:$A$400,$A20,'Promo Calendar'!$I$6:$I$400,">"&TODAY())=0,"None scheduled",_xlfn.MINIFS('Promo Calendar'!$I$6:$I$400,'Promo Calendar'!$A$6:$A$400,$A20,'Promo Calendar'!$I$6:$I$400,">"&TODAY()))) | R20: Ensure shelves are merchandised. Sufficient inventory in backstock. | T20: HW Hot Sheet 8/25/25 | U20: Confirm for 2026 | W20: =IF($A20="","",COUNTIFS('Visit Log'!$C$6:$C$1005,$A20,'Visit Log'!$A$6:$A$1005,">="&TODAY()-30)) | X20: =IF($A20="","",COUNTIFS('Visit Log'!$C$6:$C$1005,$A20,'Visit Log'!$T$6:$T$1005,"Open")+COUNTIFS('Visit Log'!$C$6:$C$1005,$A20,'Visit Log'!$T$6:$T$1005,"In Progress")) | Y20: =IF($A20="","",IF(COUNTIFS('Visit Log'!$C$6:$C$1005,$A20)=0,"No visits",_xlfn.MAXIFS('Visit Log'!$A$6:$A$1005,'Visit Log'!$C$6:$C$1005,$A20)))
A21: Henry's | NorCal Div. #25 (incl. HI) | B21: Henry's | C21: Albertsons/Safeway | D21: NorCal Div. #25 (incl. HI) | E21: NorCal / HI | H21: Root Beer, Orange Cream, Vanilla Cream; Black Cherry Cream select stores | I21: 1 case of each flavor backstock | J21: Shelves merchandised; backstock | L21: SRP $7.99 (HI $8.99) | M21: 7.99 | N21: 2025: 6/1-9/6, 10/5-1/3 | O21: =IF($A21="","",IF(COUNTIFS('Promo Calendar'!$A$6:$A$400,$A21,'Promo Calendar'!$L$6:$L$400,"Active")=0,"None active",INDEX('Promo Calendar'!$F$6:$F$400,MATCH($A21,'Promo Calendar'!$O$6:$O$400,0))&IF(COUNTIFS('Promo Calendar'!$A$6:$A$400,$A21,'Promo Calendar'!$L$6:$L$400,"Active")>1," (+"&(COUNTIFS('Promo Calendar'!$A$6:$A$400,$A21,'Promo Calendar'!$L$6:$L$400,"Active")-1)&" more)",""))) | P21: =IF($A21="","",IF(COUNTIFS('Promo Calendar'!$A$6:$A$400,$A21,'Promo Calendar'!$L$6:$L$400,"Active",'Promo Calendar'!$G$6:$G$400,">0")>0,_xlfn.MINIFS('Promo Calendar'!$G$6:$G$400,'Promo Calendar'!$A$6:$A$400,$A21,'Promo Calendar'!$L$6:$L$400,"Active",'Promo Calendar'!$G$6:$G$400,">0"),IF(M21="","Not set",M21))) | Q21: =IF($A21="","",IF(COUNTIFS('Promo Calendar'!$A$6:$A$400,$A21,'Promo Calendar'!$I$6:$I$400,">"&TODAY())=0,"None scheduled",_xlfn.MINIFS('Promo Calendar'!$I$6:$I$400,'Promo Calendar'!$A$6:$A$400,$A21,'Promo Calendar'!$I$6:$I$400,">"&TODAY()))) | R21: Ensure shelves are merchandised. Sufficient inventory in backstock. Hawaii SRP $8.99 / TPR $7.99. | T21: HW Hot Sheet 8/25/25 | U21: Confirm for 2026 | W21: =IF($A21="","",COUNTIFS('Visit Log'!$C$6:$C$1005,$A21,'Visit Log'!$A$6:$A$1005,">="&TODAY()-30)) | X21: =IF($A21="","",COUNTIFS('Visit Log'!$C$6:$C$1005,$A21,'Visit Log'!$T$6:$T$1005,"Open")+COUNTIFS('Visit Log'!$C$6:$C$1005,$A21,'Visit Log'!$T$6:$T$1005,"In Progress")) | Y21: =IF($A21="","",IF(COUNTIFS('Visit Log'!$C$6:$C$1005,$A21)=0,"No visits",_xlfn.MAXIFS('Visit Log'!$A$6:$A$1005,'Visit Log'!$C$6:$C$1005,$A21)))
